<robot name="luna_rover">

    <link name="chassis_footprint">

    </link>
    
    <link name="chassis_link">
        <inertial>
            <origin xyz="0.0 0.0 0.0" rpy="0.0 0.0 0.0"/>
            <mass value="35.0"/>
            <inertia ixx="0.915" ixy="0.0" iyy="0.410" iyz="0.0 izz="0.325"/>
        </inertial>
        <visual name="">
            <origin xyz="0.0 0.0 0.0" rpy="0.0 0.0 0.0"/>
            <geometry>
                <box size="0.56 0.375 0.01"/>
            </geometry>
            <material name="blue">
                <color rgba="0.0 0.0 1.0 1.0"/>
            </material>
        </visual>
        <collision>
            <origin xyz="0.0 0.0 0.0" rpy="0.0 0.0 0.0"/>
            <geometry>
                <box size="0.56 0.375 0.01"/>
            </geometry>
        </collision>
    </link>

    <joint name="chassis_joint" type="fixed">
        <origin xyz="0.0 0.0 0.0127" rpy="0.0 0.0 0.0"/>
        <parent link="chassis_footprint"/>
        <child link="chassis_link"/>
        <axis xyz="0.0 0.0 0.0"/>
    </joint>

    <!-- Rear Right Wheel -->
    <link name="r_r_wheel">
        <inertial>
            <origin xyz="0.0 0.0 0.0" rpy="0.0 0.0 0.0"/>
            <mass value="0.0"/>
            <inertia ixx="0.0" ixy="0.0" iyy="0.0" iyz="0.0 izz="0.0"/>
        </inertial>
        <visual name="">
            <origin xyz="0.0 0.0 0.0" rpy="0.0 0.0 0.0"/>
            <geometry>
                <cylinder radius="0.0127" length="0.00762"/>
            </geometry>
            <material name="black">
                <color rgba="0.0 0.0 0.0 1.0"/>
            </material>
        </visual>
        <collision>
            <origin xyz="0.0 0.0 0.0" rpy="0.0 0.0 0.0"/>
            <geometry>
                <cylinder radius="0.0127" length="0.00762"/>
            </geometry>
        </collision>
    </link>

    <joint name="r_r_wheel_joint" type="continuous">
        <origin xyz="0.28 0.1875 0.0127" rpy="1.57 0.0 0.0"/>
        <parent link="chassis_link"/>
        <child link="r_r_wheel"/>
        <axis xyz="1.0 0.0 0.0"/>
    </joint>

    <!-- Rear Left Wheel -->
    <link name="r_l_wheel">
        <inertial>
            <origin xyz="0.0 0.0 0.0" rpy="0.0 0.0 0.0"/>
            <mass value="0.0"/>
            <inertia ixx="0.0" ixy="0.0" iyy="0.0" iyz="0.0 izz="0.0"/>
        </inertial>
        <visual name="">
            <origin xyz="0.0 0.0 0.0" rpy="0.0 0.0 0.0"/>
            <geometry>
                <cylinder radius="0.0127" length="0.00762"/>
            </geometry>
                <material name="black">
                <color rgba="0.0 0.0 0.0 1.0"/>
            </material>
        </visual>
        <collision>
            <origin xyz="0.0 0.0 0.0" rpy="0.0 0.0 0.0"/>
            <geometry>
                <cylinder radius="0.0127" length="0.00762"/>
            </geometry>
        </collision>
    </link>

    <joint name="r_l_wheel_joint" type="continuous">
        <origin xyz="0.28 -0.1875 0.0127" rpy="1.57 0.0 0.0"/>
        <parent link="chassis_link"/>
        <child link="r_l_wheel"/>
        <axis xyz="1.0 0.0 0.0"/>
    </joint>

        <!-- Front Right Wheel -->
    <link name="f_r_wheel">
        <inertial>
            <origin xyz="0.0 0.0 0.0" rpy="0.0 0.0 0.0"/>
            <mass value="0.0"/>
            <inertia ixx="0.0" ixy="0.0" iyy="0.0" iyz="0.0 izz="0.0"/>
        </inertial>
        <visual name="">
            <origin xyz="0.0 0.0 0.0" rpy="0.0 0.0 0.0"/>
            <geometry>
                <cylinder radius="0.0127" length="0.00762"/>
            </geometry>
            <material name="black">
                <color rgba="0.0 0.0 0.0 1.0"/>
            </material>
        </visual>
        <collision>
            <origin xyz="0.0 0.0 0.0" rpy="0.0 0.0 0.0"/>
            <geometry>
                <cylinder radius="0.0127" length="0.00762"/>
            </geometry>
        </collision>
    </link>

    <joint name="f_r_wheel_joint" type="continuous">
        <origin xyz="-0.28 0.1875 0.0127" rpy="1.57 0.0 0.0"/>
        <parent link="chassis_link"/>
        <child link="f_r_wheel"/>
        <axis xyz="1.0 0.0 0.0"/>
    </joint>

    <!-- Front Left Wheel -->
    <link name="f_l_wheel">
        <inertial>
            <origin xyz="0.0 0.0 0.0" rpy="0.0 0.0 0.0"/>
            <mass value="0.0"/>
            <inertia ixx="0.0" ixy="0.0" iyy="0.0" iyz="0.0 izz="0.0"/>
        </inertial>
        <visual name="">
            <origin xyz="0.0 0.0 0.0" rpy="0.0 0.0 0.0"/>
            <geometry>
                <cylinder radius="0.0127" length="0.00762"/>
            </geometry>
            <material name="black">
                <color rgba="0.0 0.0 0.0 1.0"/>
            </material>
        </visual>
        <collision>
            <origin xyz="0.0 0.0 0.0" rpy="0.0 0.0 0.0"/>
            <geometry>
                <cylinder radius="0.0127" length="0.00762"/>
            </geometry>
        </collision>
    </link>

    <joint name="f_l_wheel_joint" type="continuous">
        <origin xyz="-0.28 -0.1875 0.0127" rpy="1.57 0.0 0.0"/>
        <parent link="chassis_link"/>
        <child link="f_l_wheel"/>
        <axis xyz="1.0 0.0 0.0"/>
    </joint>

</robot>